Workbook

Sheet Uebersetzung_ccm
B1: Berechnet für Continuous Conduction Mode
B4: d und U1 werden nährungsweise Konstant gehalten / jeder erste Wert in einem Messreihen block ist nahe am "Anfang des CCM" => critical conduction mode aufgenommen
B5: Thermische EInschwingzeit: 2-5 min | N5: SerienWdst des Kabels ist hier nicht mit erfasst
B6: Ansteuerung | C6: Ü_ideal | D6: Messung | E6: Messwerte | I6: Rechenwerte | N6: Stellwert
B7: d | C7: Ü | D7: Name | E7: U1 [V] | F7: I1 [A] | G7: U2 [V] | H7: I2 [A] | I7: U2/U1 | J7: P1 [W] | K7: P2 [W] | L7: Pdiff [W] | M7: P2/P1 | N7: R_L [Ω]
B8: 0.05 | C8: =1/(1-2*B8) -> 1.1111111 | D8: =TEXT(ROUND(E8,3),"#,#")&"_"&TEXT(B8,"0,##") -> 3,3_0,05 | E8: 3.30405 | F8: 0.06294 | G8: 3.0772 | H8: 0.05115 | I8: =G8/E8 -> 0.93134184 | J8: =F8*E8 -> 0.20795691 | K8: =H8*G8 -> 0.15739878 | L8: =J8-K8 -> 0.050558127 | M8: =K8/J8 -> 0.75688171 | N8: 60
B9: 0.05 | C9: =1/(1-2*B9) -> 1.1111111 | D9: =TEXT(ROUND(E9,3),"#,#")&"_"&TEXT(B9,"0,##") -> 3,3_0,05 | E9: 3.3 | F9: 0.11624 | G9: 2.9701 | H9: 0.09807 | I9: =G9/E9 -> 0.9000303 | J9: =F9*E9 -> 0.383592 | K9: =H9*G9 -> 0.29127771 | L9: =J9-K9 -> 0.092314293 | M9: =K9/J9 -> 0.7593425 | N9: 30
B10: 0.05 | C10: =1/(1-2*B10) -> 1.1111111 | D10: =TEXT(ROUND(E10,3),"#,#")&"_"&TEXT(B10,"0,##") -> 3,3_0,05 | E10: 3.3019 | F10: 0.22152 | G10: 2.88198 | H10: 0.19116 | I10: =G10/E10 -> 0.87282474 | J10: =F10*E10 -> 0.73143689 | K10: =H10*G10 -> 0.5509193 | L10: =J10-K10 -> 0.18051759 | M10: =K10/J10 -> 0.75320141 | N10: 15
B11: 0.05 | C11: =1/(1-2*B11) -> 1.1111111 | D11: =TEXT(ROUND(E11,3),"#,#")&"_"&TEXT(B11,"0,##") -> 3,3_0,05 | E11: 3.307 | F11: 0.859 | G11: 2.7061 | H11: 0.75788 | I11: =G11/E11 -> 0.81829453 | J11: =F11*E11 -> 2.840713 | K11: =H11*G11 -> 2.0508991 | L11: =J11-K11 -> 0.78981393 | M11: =K11/J11 -> 0.7219663 | N11: 3.5
B12: 0.05 | C12: =1/(1-2*B12) -> 1.1111111 | D12: =TEXT(ROUND(E12,3),"#,#")&"_"&TEXT(B12,"0,##") -> 3,3_0,05 | E12: 3.3096 | F12: 2.5928 | G12: 2.4666 | H12: 2.29875 | I12: =G12/E12 -> 0.74528644 | J12: =F12*E12 -> 8.5811309 | K12: =H12*G12 -> 5.6700968 | L12: =J12-K12 -> 2.9110341 | M12: =K12/J12 -> 0.66076335 | N12: 1
B13: 0.05 | C13: =1/(1-2*B13) -> 1.1111111 | D13: =TEXT(ROUND(E13,3),"#,#")&"_"&TEXT(B13,"0,##") -> 3,3_0,05 | E13: 3.305 | F13: 4.4095 | G13: 2.253 | H13: 3.92205 | I13: =G13/E13 -> 0.6816944 | J13: =F13*E13 -> 14.573398 | K13: =H13*G13 -> 8.8363787 | L13: =J13-K13 -> 5.7370189 | M13: =K13/J13 -> 0.60633621 | N13: 0.5
B14: 0.05 | C14: =1/(1-2*B14) -> 1.1111111 | D14: =TEXT(ROUND(E14,3),"#,#")&"_"&TEXT(B14,"0,##") -> 3,3_0,05 | E14: 3.301 | F14: 6.0558 | G14: 2.136 | H14: 5.404 | I14: =G14/E14 -> 0.64707664 | J14: =F14*E14 -> 19.990196 | K14: =H14*G14 -> 11.542944 | L14: =J14-K14 -> 8.4472518 | M14: =K14/J14 -> 0.57743026 | N14: 0.4
B16: 0.05 | C16: =1/(1-2*B16) -> 1.1111111 | D16: =TEXT(ROUND(E16,3),"#")&"_"&TEXT(B16,"0,##") -> 5_0,05 | E16: 5.01726 | F16: 0.10141 | G16: 5.02257 | H16: 0.083333 | I16: =G16/E16 -> 1.0010583 | J16: =F16*E16 -> 0.50880034 | K16: =H16*G16 -> 0.41854583 | L16: =J16-K16 -> 0.090254511 | M16: =K16/J16 -> 0.82261311 | N16: 60
B17: 0.05 | C17: =1/(1-2*B17) -> 1.1111111 | D17: =TEXT(ROUND(E17,3),"#")&"_"&TEXT(B17,"0,##") -> 5_0,05 | E17: 5.00435 | F17: 0.18967 | G17: 4.8851 | H17: 0.16108 | I17: =G17/E17 -> 0.97617073 | J17: =F17*E17 -> 0.94917506 | K17: =H17*G17 -> 0.78689191 | L17: =J17-K17 -> 0.16228316 | M17: =K17/J17 -> 0.82902716 | N17: 30
B18: 0.05 | C18: =1/(1-2*B18) -> 1.1111111 | D18: =TEXT(ROUND(E18,3),"#")&"_"&TEXT(B18,"0,##") -> 5_0,05 | E18: 5.0016 | F18: 0.36546 | G18: 4.77228 | H18: 0.31658 | I18: =G18/E18 -> 0.95415067 | J18: =F18*E18 -> 1.8278847 | K18: =H18*G18 -> 1.5108084 | L18: =J18-K18 -> 0.31707633 | M18: =K18/J18 -> 0.82653374 | N18: 15
B19: 0.05 | C19: =1/(1-2*B19) -> 1.1111111 | D19: =TEXT(ROUND(E19,3),"#")&"_"&TEXT(B19,"0,##") -> 5_0,05 | E19: 5.0093 | F19: 0.70452 | G19: 4.676 | H19: 0.61728 | I19: =G19/E19 -> 0.93346376 | J19: =F19*E19 -> 3.529152 | K19: =H19*G19 -> 2.8864013 | L19: =J19-K19 -> 0.64275076 | M19: =K19/J19 -> 0.81787388 | N19: 7.5
B20: 0.05 | C20: =1/(1-2*B20) -> 1.1111111 | D20: =TEXT(ROUND(E20,3),"#")&"_"&TEXT(B20,"0,##") -> 5_0,05 | E20: 5.009 | F20: 1.96926 | G20: 4.4708 | H20: 1.73965 | I20: =G20/E20 -> 0.8925534 | J20: =F20*E20 -> 9.8640233 | K20: =H20*G20 -> 7.7776272 | L20: =J20-K20 -> 2.0863961 | M20: =K20/J20 -> 0.78848427 | N20: 2.5
B21: 0.05 | C21: =1/(1-2*B21) -> 1.1111111 | D21: =TEXT(ROUND(E21,3),"#")&"_"&TEXT(B21,"0,##") -> 5_0,05 | E21: 5.001 | F21: 4.4099 | G21: 4.1908 | H21: 3.90597 | I21: =G21/E21 -> 0.8379924 | J21: =F21*E21 -> 22.05391 | K21: =H21*G21 -> 16.369139 | L21: =J21-K21 -> 5.6847708 | M21: =K21/J21 -> 0.74223297 | N21: 1
B22: 0.05 | C22: =1/(1-2*B22) -> 1.1111111 | D22: =TEXT(ROUND(E22,3),"#")&"_"&TEXT(B22,"0,##") -> 5_0,05 | E22: 5.005 | F22: 5.928 | G22: 4.0716 | H22: 5.2574 | I22: =G22/E22 -> 0.81350649 | J22: =F22*E22 -> 29.66964 | K22: =H22*G22 -> 21.40603 | L22: =J22-K22 -> 8.2636102 | M22: =K22/J22 -> 0.72147926 | N22: 0.7
B24: 0.05 | C24: =1/(1-2*B24) -> 1.1111111 | D24: =TEXT(ROUND(E24,3),"#")&"_"&TEXT(B24,"0,##") -> 9_0,05 | E24: 9.0563 | F24: 0.148255 | G24: 9.724 | H24: 0.12135 | I24: =G24/E24 -> 1.0737277 | J24: =F24*E24 -> 1.3426418 | K24: =H24*G24 -> 1.1800074 | L24: =J24-K24 -> 0.16263436 | M24: =K24/J24 -> 0.87886988 | N24: 80
B25: 0.05 | C25: =1/(1-2*B25) -> 1.1111111 | D25: =TEXT(ROUND(E25,3),"#")&"_"&TEXT(B25,"0,##") -> 9_0,05 | E25: 9.0165 | F25: 0.2791 | G25: 9.493 | H25: 0.2365 | I25: =G25/E25 -> 1.0528476 | J25: =F25*E25 -> 2.5165052 | K25: =H25*G25 -> 2.2450945 | L25: =J25-K25 -> 0.27141065 | M25: =K25/J25 -> 0.89214779 | N25: 40
B26: 0.05 | C26: =1/(1-2*B26) -> 1.1111111 | D26: =TEXT(ROUND(E26,3),"#")&"_"&TEXT(B26,"0,##") -> 9_0,05 | E26: 9.0021 | F26: 0.537126 | G26: 9.3155 | H26: 0.46454 | I26: =G26/E26 -> 1.0348141 | J26: =F26*E26 -> 4.835262 | K26: =H26*G26 -> 4.3274224 | L26: =J26-K26 -> 0.50783959 | M26: =K26/J26 -> 0.89497165 | N26: 20
B27: 0.05 | C27: =1/(1-2*B27) -> 1.1111111 | D27: =TEXT(ROUND(E27,3),"#")&"_"&TEXT(B27,"0,##") -> 9_0,05 | E27: 9.0065 | F27: 1.04045 | G27: 9.1715 | H27: 0.910436 | I27: =G27/E27 -> 1.0183201 | J27: =F27*E27 -> 9.3708129 | K27: =H27*G27 -> 8.3500638 | L27: =J27-K27 -> 1.0207492 | M27: =K27/J27 -> 0.89107144 | N27: 10
B28: 0.05 | C28: =1/(1-2*B28) -> 1.1111111 | D28: =TEXT(ROUND(E28,3),"#")&"_"&TEXT(B28,"0,##") -> 9_0,05 | E28: 9.0083 | F28: 2.01844 | G28: 9.0065 | H28: 1.7768 | I28: =G28/E28 -> 0.99980018 | J28: =F28*E28 -> 18.182713 | K28: =H28*G28 -> 16.002749 | L28: =J28-K28 -> 2.1799639 | M28: =K28/J28 -> 0.88010789 | N28: 5
... B42: 0.05 | C42: =1/(1-2*B42) -> 1.1111111 | D42: =TEXT(ROUND(E42,3),"#")&"_"&TEXT(B42,"0,##") -> 24_0,05 | E42: 24.0136 | F42: 5.7665 | G42: 25.61 | H42: 5.0635 | I42: =G42/E42 -> 1.066479 | J42: =F42*E42 -> 138.47442 | K42: =H42*G42 -> 129.67624 | L42: =J42-K42 -> 8.7981894 | M42: =K42/J42 -> 0.93646343 | N42: 5
B44: 0.1 | C44: =1/(1-2*B44) -> 1.25 | D44: =TEXT(ROUND(E44,3),"#,#")&"_"&TEXT(B44,"0,##") -> 3,3_0,1 | E44: 3.3016 | F44: 0.10331 | G44: 3.456 | H44: 0.07576 | I44: =G44/E44 -> 1.0467652 | J44: =F44*E44 -> 0.3410883 | K44: =H44*G44 -> 0.26182656 | L44: =J44-K44 -> 0.079261736 | M44: =K44/J44 -> 0.76762106 | N44: 45
B45: 0.1 | C45: =1/(1-2*B45) -> 1.25 | D45: =TEXT(ROUND(E45,3),"#,#")&"_"&TEXT(B45,"0,##") -> 3,3_0,1 | E45: 3.3011 | F45: 0.21765 | G45: 3.3251 | H45: 0.16529 | I45: =G45/E45 -> 1.0072703 | J45: =F45*E45 -> 0.71848442 | K45: =H45*G45 -> 0.54960578 | L45: =J45-K45 -> 0.16887864 | M45: =K45/J45 -> 0.76495157 | N45: 20
B46: 0.1 | C46: =1/(1-2*B46) -> 1.25 | D46: =TEXT(ROUND(E46,3),"#,#")&"_"&TEXT(B46,"0,##") -> 3,3_0,1 | E46: 3.3007 | F46: 0.41561 | G46: 3.2279 | H46: 0.320795 | I46: =G46/E46 -> 0.97794407 | J46: =F46*E46 -> 1.3718039 | K46: =H46*G46 -> 1.0354942 | L46: =J46-K46 -> 0.33630975 | M46: =K46/J46 -> 0.75484124 | N46: 10
B47: 0.1 | C47: =1/(1-2*B47) -> 1.25 | D47: =TEXT(ROUND(E47,3),"#,#")&"_"&TEXT(B47,"0,##") -> 3,3_0,1 | E47: 3.3019 | F47: 0.7904 | G47: 3.1253 | H47: 0.6169 | I47: =G47/E47 -> 0.94651564 | J47: =F47*E47 -> 2.6098218 | K47: =H47*G47 -> 1.9279976 | L47: =J47-K47 -> 0.68182419 | M47: =K47/J47 -> 0.73874684 | N47: 5
B48: 0.1 | C48: =1/(1-2*B48) -> 1.25 | D48: =TEXT(ROUND(E48,3),"#,#")&"_"&TEXT(B48,"0,##") -> 3,3_0,1 | E48: 3.3001 | F48: 1.48342 | G48: 2.9888 | H48: 1.1625 | I48: =G48/E48 -> 0.90566953 | J48: =F48*E48 -> 4.8954343 | K48: =H48*G48 -> 3.47448 | L48: =J48-K48 -> 1.4209543 | M48: =K48/J48 -> 0.70973886 | N48: 2.5
B49: 0.1 | C49: =1/(1-2*B49) -> 1.25 | D49: =TEXT(ROUND(E49,3),"#,#")&"_"&TEXT(B49,"0,##") -> 3,3_0,1 | E49: 3.3005 | F49: 3.233 | G49: 2.7245 | H49: 2.54236 | I49: =G49/E49 -> 0.82548099 | J49: =F49*E49 -> 10.670516 | K49: =H49*G49 -> 6.9266598 | L49: =J49-K49 -> 3.7438567 | M49: =K49/J49 -> 0.64914007 | N49: 1
B50: 0.1 | C50: =1/(1-2*B50) -> 1.25 | D50: =TEXT(ROUND(E50,3),"#,#")&"_"&TEXT(B50,"0,##") -> 3,3_0,1 | E50: 3.302 | F50: 5.8326 | G50: 2.416 | H50: 4.6082 | I50: =G50/E50 -> 0.73167777 | J50: =F50*E50 -> 19.259245 | K50: =H50*G50 -> 11.133411 | L50: =J50-K50 -> 8.125834 | M50: =K50/J50 -> 0.57808139 | N50: 0.45
B52: 0.1 | C52: =1/(1-2*B52) -> 1.25 | D52: =TEXT(ROUND(E52,3),"#")&"_"&TEXT(B52,"0,##") -> 5_0,1 | E52: 5.00227 | F52: 0.16778 | G52: 5.6085 | H52: 0.12429 | I52: =G52/E52 -> 1.121191 | J52: =F52*E52 -> 0.83928086 | K52: =H52*G52 -> 0.69708046 | L52: =J52-K52 -> 0.1422004 | M52: =K52/J52 -> 0.83056876 | N52: 45
B53: 0.1 | C53: =1/(1-2*B53) -> 1.25 | D53: =TEXT(ROUND(E53,3),"#")&"_"&TEXT(B53,"0,##") -> 5_0,1 | E53: 5.00058 | F53: 0.35703 | G53: 5.4702 | H53: 0.27246 | I53: =G53/E53 -> 1.0939131 | J53: =F53*E53 -> 1.7853571 | K53: =H53*G53 -> 1.4904107 | L53: =J53-K53 -> 0.29494639 | M53: =K53/J53 -> 0.83479698 | N53: 20
B54: 0.1 | C54: =1/(1-2*B54) -> 1.25 | D54: =TEXT(ROUND(E54,3),"#")&"_"&TEXT(B54,"0,##") -> 5_0,1 | E54: 5.0042 | F54: 0.68466 | G54: 5.3447 | H54: 0.52985 | I54: =G54/E54 -> 1.0680428 | J54: =F54*E54 -> 3.4261756 | K54: =H54*G54 -> 2.8318893 | L54: =J54-K54 -> 0.59428628 | M54: =K54/J54 -> 0.82654529 | N54: 10
B55: 0.1 | C55: =1/(1-2*B55) -> 1.25 | D55: =TEXT(ROUND(E55,3),"#")&"_"&TEXT(B55,"0,##") -> 5_0,1 | E55: 5.0006 | F55: 1.3139 | G55: 5.1987 | H55: 1.024828 | I55: =G55/E55 -> 1.0396152 | J55: =F55*E55 -> 6.5702883 | K55: =H55*G55 -> 5.3277733 | L55: =J55-K55 -> 1.242515 | M55: =K55/J55 -> 0.81088881 | N55: 5
B56: 0.1 | C56: =1/(1-2*B56) -> 1.25 | D56: =TEXT(ROUND(E56,3),"#")&"_"&TEXT(B56,"0,##") -> 5_0,1 | E56: 5.0001 | F56: 2.4771 | G56: 5.0045 | H56: 1.9396 | I56: =G56/E56 -> 1.00088 | J56: =F56*E56 -> 12.385748 | K56: =H56*G56 -> 9.7067282 | L56: =J56-K56 -> 2.6790195 | M56: =K56/J56 -> 0.78370143 | N56: 2.5
B57: 0.1 | C57: =1/(1-2*B57) -> 1.25 | D57: =TEXT(ROUND(E57,3),"#")&"_"&TEXT(B57,"0,##") -> 5_0,1 | E57: 5.002 | F57: 5.46425 | G57: 4.6263 | H57: 4.2918 | I57: =G57/E57 -> 0.92489004 | J57: =F57*E57 -> 27.332178 | K57: =H57*G57 -> 19.855154 | L57: =J57-K57 -> 7.4770242 | M57: =K57/J57 -> 0.72643878 | N57: 1
B59: 0.1 | C59: =1/(1-2*B59) -> 1.25 | D59: =TEXT(ROUND(E59,3),"#")&"_"&TEXT(B59,"0,##") -> 9_0,1 | E59: 9.00177 | F59: 0.26086 | G59: 10.6923 | H59: 0.19339 | I59: =G59/E59 -> 1.1877997 | J59: =F59*E59 -> 2.3482017 | K59: =H59*G59 -> 2.0677839 | L59: =J59-K59 -> 0.28041783 | M59: =K59/J59 -> 0.88058188 | N59: 55
B60: 0.1 | C60: =1/(1-2*B60) -> 1.25 | D60: =TEXT(ROUND(E60,3),"#")&"_"&TEXT(B60,"0,##") -> 9_0,1 | E60: 9.0086 | F60: 0.5027 | G60: 10.5445 | H60: 0.3826 | I60: =G60/E60 -> 1.1704926 | J60: =F60*E60 -> 4.5286232 | K60: =H60*G60 -> 4.0343257 | L60: =J60-K60 -> 0.49429752 | M60: =K60/J60 -> 0.89085038 | N60: 27.5
...

Sheet Wirkungsgradkurven
B1: Wirkungsgradkurven
B4: U1 und U2 werden nährungsweise Konstant gehalten, Converter im dcm und ccm Betrieb je nach Last
B5: Thermische EInschwingzeit: 2-5 min | N5: SerienWdst des Kabels ist hier nicht mit erfasst
B6: Ansteuerung | C6: Betriebszustand | D6: Messung | E6: Messwerte | I6: Rechenwerte | N6: Stellwert | O6: Referenz [M_d_Vin_Vout_Pout]
B7: d | C7: M | D7: Name | E7: U1 [V] | F7: I1 [A] | G7: U2 [V] | H7: I2 [A] | I7: U2/U1 | J7: P1 [W] | K7: P2 [W] | L7: Pdiff [W] | M7: P2/P1 | N7: R_L [Ω]
B8: 0.299 | C8: dcm | D8: =TEXT(ROUND(E8,3),"#,#")&"_"&TEXT(G8,"0") -> 3,3_12 | E8: 3.30001 | F8: 0.43375 | G8: 12.06 | H8: 0.08328 | I8: =G8/E8 -> 3.6545344 | J8: =F8*E8 -> 1.4313793 | K8: =H8*G8 -> 1.0043568 | L8: =J8-K8 -> 0.42702254 | M8: =K8/J8 -> 0.7016706 | N8: 144
B9: 0.38 | C9: ccm | D9: =TEXT(ROUND(E9,3),"#,#")&"_"&TEXT(G9,"0") -> 3,3_12 | E9: 3.3001 | F9: 1.0337 | G9: 12.061 | H9: 0.2092 | I9: =G9/E9 -> 3.6547377 | J9: =F9*E9 -> 3.4113134 | K9: =H9*G9 -> 2.5231612 | L9: =J9-K9 -> 0.88815217 | M9: =K9/J9 -> 0.73964509 | N9: 57.6
B10: 0.388 | C10: ccm | D10: =TEXT(ROUND(E10,3),"#,#")&"_"&TEXT(G10,"0") -> 3,3_12 | E10: 3.3012 | F10: 2.09906 | G10: 12.0345 | H10: 0.41532 | I10: =G10/E10 -> 3.6454925 | J10: =F10*E10 -> 6.9294169 | K10: =H10*G10 -> 4.9981685 | L10: =J10-K10 -> 1.9312483 | M10: =K10/J10 -> 0.72129714 | N10: 28.8
B11: 0.394 | C11: ccm | D11: =TEXT(ROUND(E11,3),"#,#")&"_"&TEXT(G11,"0") -> 3,3_12 | E11: 3.3022 | F11: 3.299 | G11: 12.045 | H11: 0.62329 | I11: =G11/E11 -> 3.6475683 | J11: =F11*E11 -> 10.893958 | K11: =H11*G11 -> 7.5075281 | L11: =J11-K11 -> 3.3864297 | M11: =K11/J11 -> 0.68914606 | N11: 19.2
B12: 0.398 | C12: ccm | D12: =TEXT(ROUND(E12,3),"#,#")&"_"&TEXT(G12,"0") -> 3,3_12 | E12: 3.2995 | F12: 4.7066 | G12: 12.065 | H12: 0.8308 | I12: =G12/E12 -> 3.6566146 | J12: =F12*E12 -> 15.529427 | K12: =H12*G12 -> 10.023602 | L12: =J12-K12 -> 5.5058247 | M12: =K12/J12 -> 0.6454586 | N12: 14.4
B13: 0.404 | C13: ccm | D13: =TEXT(ROUND(E13,3),"#,#")&"_"&TEXT(G13,"0") -> 3,3_12 | E13: 3.3002 | F13: 5.8208 | G13: 12.073 | H13: 0.99557 | I13: =G13/E13 -> 3.6582631 | J13: =F13*E13 -> 19.209804 | K13: =H13*G13 -> 12.019517 | L13: =J13-K13 -> 7.1902876 | M13: =K13/J13 -> 0.62569699 | N13: 12
B15: 0.272 | C15: dcm | D15: =TEXT(ROUND(E15,3),"#,#")&"_"&TEXT(G15,"0") -> 3,3_24 | E15: 3.3075 | F15: 0.5991 | G15: 24.048 | H15: 0.04808 | I15: =G15/E15 -> 7.2707483 | J15: =F15*E15 -> 1.9815232 | K15: =H15*G15 -> 1.1562278 | L15: =J15-K15 -> 0.82529541 | M15: =K15/J15 -> 0.58350455 | N15: 500 | O15: =C15&"_"&TEXT(B15,"0,####")&"_"&TEXT(ROUND(E15,3),"#,#")&"_"&TEXT(G15,"0")&"_"&TEXT(ROUND(K15,1),"0,##") -> dcm_0,272_3,3_24_1,2
B16: 0.435 | C16: ccm | D16: =TEXT(ROUND(E16,3),"#,#")&"_"&TEXT(G16,"0") -> 3,3_24 | E16: 3.3079 | F16: 1.2416 | G16: 24.016 | H16: 0.1045 | I16: =G16/E16 -> 7.2601953 | J16: =F16*E16 -> 4.1070886 | K16: =H16*G16 -> 2.509672 | L16: =J16-K16 -> 1.5974166 | M16: =K16/J16 -> 0.61105864 | N16: 230
B17: 0.4395 | C17: ccm | D17: =TEXT(ROUND(E17,3),"#,#")&"_"&TEXT(G17,"0") -> 3,3_24 | E17: 3.3068 | F17: 2.3834 | G17: 24.033 | H17: 0.20863 | I17: =G17/E17 -> 7.2677513 | J17: =F17*E17 -> 7.8814271 | K17: =H17*G17 -> 5.0140048 | L17: =J17-K17 -> 2.8674223 | M17: =K17/J17 -> 0.63617981 | N17: 115
B18: 0.4423 | C18: ccm | D18: =TEXT(ROUND(E18,3),"#,#")&"_"&TEXT(G18,"0") -> 3,3_24 | E18: 3.3009 | F18: 3.6325 | G18: 24.09 | H18: 0.3125 | I18: =G18/E18 -> 7.2980096 | J18: =F18*E18 -> 11.990519 | K18: =H18*G18 -> 7.528125 | L18: =J18-K18 -> 4.4623942 | M18: =K18/J18 -> 0.62783978 | N18: 76 | O18: =C18&"_"&TEXT(B18,"0,####")&"_"&TEXT(ROUND(E18,3),"#,#")&"_"&TEXT(G18,"0")&"_"&TEXT(ROUND(K18,1),"0,##") -> ccm_0,4423_3,3_24_7,5
B19: 0.4453 | C19: ccm | D19: =TEXT(ROUND(E19,3),"#,#")&"_"&TEXT(G19,"0") -> 3,3_24 | E19: 3.3 | F19: 5.02 | G19: 24.068 | H19: 0.41426 | I19: =G19/E19 -> 7.2933333 | J19: =F19*E19 -> 16.566 | K19: =H19*G19 -> 9.9704097 | L19: =J19-K19 -> 6.5955903 | M19: =K19/J19 -> 0.60185981 | N19: 58
B20: 0.447 | C20: ccm | D20: =TEXT(ROUND(E20,3),"#,#")&"_"&TEXT(G20,"0") -> 3,3_24 | E20: 3.301 | F20: 6.124 | G20: 24.065 | H20: 0.48888 | I20: =G20/E20 -> 7.2902151 | J20: =F20*E20 -> 20.215324 | K20: =H20*G20 -> 11.764897 | L20: =J20-K20 -> 8.4504268 | M20: =K20/J20 -> 0.58197916 | N20: 49 | O20: =C20&"_"&TEXT(B20,"0,####")&"_"&TEXT(ROUND(E20,3),"#,#")&"_"&TEXT(G20,"0")&"_"&TEXT(ROUND(K20,1),"0,##") -> ccm_0,447_3,3_24_11,8
B22: 0.125 | C22: dcm | D22: =TEXT(ROUND(E22,3),"#,#")&"_"&TEXT(G22,"0") -> 5,_12 | E22: 5.004 | F22: 0.122 | G22: 12.05 | H22: 0.0399 | I22: =G22/E22 -> 2.4080735 | J22: =F22*E22 -> 0.610488 | K22: =H22*G22 -> 0.480795 | L22: =J22-K22 -> 0.129693 | M22: =K22/J22 -> 0.78755848 | N22: 300 | O22: =C22&"_"&TEXT(B22,"0,####")&"_"&TEXT(ROUND(E22,3),"#,#")&"_"&TEXT(G22,"0")&"_"&TEXT(ROUND(K22,1),"0,##") -> dcm_0,125_5,_12_0,5
B23: 0.184 | C23: dcm | D23: =TEXT(ROUND(E23,3),"#,#")&"_"&TEXT(G23,"0") -> 5,_12 | E23: 5.0109 | F23: 0.2491 | G23: 12.003 | H23: 0.0831 | I23: =G23/E23 -> 2.3953781 | J23: =F23*E23 -> 1.2482152 | K23: =H23*G23 -> 0.9974493 | L23: =J23-K23 -> 0.25076589 | M23: =K23/J23 -> 0.79910043 | N23: 144
B24: 0.308 | C24: ccm | D24: =TEXT(ROUND(E24,3),"#,#")&"_"&TEXT(G24,"0") -> 5,_12 | E24: 5.0073 | F24: 0.6121 | G24: 12.012 | H24: 0.20699 | I24: =G24/E24 -> 2.3988976 | J24: =F24*E24 -> 3.0649683 | K24: =H24*G24 -> 2.4863639 | L24: =J24-K24 -> 0.57860445 | M24: =K24/J24 -> 0.81122009 | N24: 57.6
B25: 0.313 | C25: ccm | D25: =TEXT(ROUND(E25,3),"#,#")&"_"&TEXT(G25,"0") -> 5,_12 | E25: 5.0129 | F25: 1.2129 | G25: 12.028 | H25: 0.4151 | I25: =G25/E25 -> 2.3994095 | J25: =F25*E25 -> 6.0801464 | K25: =H25*G25 -> 4.9928228 | L25: =J25-K25 -> 1.0873236 | M25: =K25/J25 -> 0.82116819 | N25: 28.8
B26: 0.317 | C26: ccm | D26: =TEXT(ROUND(E26,3),"#,#")&"_"&TEXT(G26,"0") -> 5,_12 | E26: 5.006 | F26: 1.8381 | G26: 12.0315 | H26: 0.62334 | I26: =G26/E26 -> 2.4034159 | J26: =F26*E26 -> 9.2015286 | K26: =H26*G26 -> 7.4997152 | L26: =J26-K26 -> 1.7018134 | M26: =K26/J26 -> 0.81505101 | N26: 19.2
B27: 0.32 | C27: ccm | D27: =TEXT(ROUND(E27,3),"#,#")&"_"&TEXT(G27,"0") -> 5,_12 | E27: 5.00978 | F27: 2.4703 | G27: 12.034 | H27: 0.82858 | I27: =G27/E27 -> 2.4021015 | J27: =F27*E27 -> 12.37566 | K27: =H27*G27 -> 9.9711317 | L27: =J27-K27 -> 2.4045278 | M27: =K27/J27 -> 0.80570508 | N27: 14.4
B28: 0.335 | C28: ccm | D28: =TEXT(ROUND(E28,3),"#,#")&"_"&TEXT(G28,"0") -> 5,_12 | E28: 5.0038 | F28: 5.811 | G28: 12.06 | H28: 1.7957 | I28: =G28/E28 -> 2.4101683 | J28: =F28*E28 -> 29.077082 | K28: =H28*G28 -> 21.656142 | L28: =J28-K28 -> 7.4209398 | M28: =K28/J28 -> 0.74478389 | N28: 6.6
B30: 0.178 | C30: dcm | D30: =TEXT(ROUND(E30,3),"#,#")&"_"&TEXT(G30,"0") -> 5,_24 | E30: 5.009 | F30: 0.319 | G30: 24 | H30: 0.0477 | I30: =G30/E30 -> 4.7913755 | J30: =F30*E30 -> 1.597871 | K30: =H30*G30 -> 1.1448 | L30: =J30-K30 -> 0.453071 | M30: =K30/J30 -> 0.71645333 | N30: 500 | O30: =C30&"_"&TEXT(B30,"0,####")&"_"&TEXT(ROUND(E30,3),"#,#")&"_"&TEXT(G30,"0")&"_"&TEXT(ROUND(K30,1),"0,##") -> dcm_0,178_5,_24_1,1
B31: 0.288 | C31: dcm | D31: =TEXT(ROUND(E31,3),"#,#")&"_"&TEXT(G31,"0") -> 5,_24 | E31: 5.0123 | F31: 0.62 | G31: 24.03 | H31: 0.096 | I31: =G31/E31 -> 4.7942063 | J31: =F31*E31 -> 3.107626 | K31: =H31*G31 -> 2.30688 | L31: =J31-K31 -> 0.800746 | M31: =K31/J31 -> 0.74232871 | N31: 230
B32: 0.401 | C32: ccm | D32: =TEXT(ROUND(E32,3),"#,#")&"_"&TEXT(G32,"0") -> 5,_24 | E32: 5.0049 | F32: 1.35288 | G32: 24.082 | H32: 0.2092 | I32: =G32/E32 -> 4.8116845 | J32: =F32*E32 -> 6.7710291 | K32: =H32*G32 -> 5.0379544 | L32: =J32-K32 -> 1.7330747 | M32: =K32/J32 -> 0.7440456 | N32: 115 | O32: =C32&"_"&TEXT(B32,"0,####")&"_"&TEXT(ROUND(E32,3),"#,#")&"_"&TEXT(G32,"0")&"_"&TEXT(ROUND(K32,1),"0,#") -> ccm_0,401_5,_24_5,
B33: 0.4032 | C33: ccm | D33: =TEXT(ROUND(E33,3),"#,#")&"_"&TEXT(G33,"0") -> 5,_24 | E33: 5.0058 | F33: 2 | G33: 24.019 | H33: 0.3156 | I33: =G33/E33 -> 4.798234 | J33: =F33*E33 -> 10.0116 | K33: =H33*G33 -> 7.5803964 | L33: =J33-K33 -> 2.4312036 | M33: =K33/J33 -> 0.75716133 | N33: 76
B34: 0.4051 | C34: ccm | D34: =TEXT(ROUND(E34,3),"#,#")&"_"&TEXT(G34,"0") -> 5,_24 | E34: 5.0063 | F34: 2.6238 | G34: 24.029 | H34: 0.4138 | I34: =G34/E34 -> 4.7997523 | J34: =F34*E34 -> 13.13553 | K34: =H34*G34 -> 9.9432002 | L34: =J34-K34 -> 3.1923297 | M34: =K34/J34 -> 0.75696986 | N34: 58
B35: 0.4115 | C35: ccm | D35: =TEXT(ROUND(E35,3),"#,#")&"_"&TEXT(G35,"0") -> 5,_24 | E35: 5.0055 | F35: 5.504 | G35: 24.068 | H35: 0.8288 | I35: =G35/E35 -> 4.8083109 | J35: =F35*E35 -> 27.550272 | K35: =H35*G35 -> 19.947558 | L35: =J35-K35 -> 7.6027136 | M35: =K35/J35 -> 0.72404216 | N35: 29
B37: 0.2291 | C37: dcm | D37: =TEXT(ROUND(E37,3),"#,#")&"_"&TEXT(G37,"0") -> 5,_48 | E37: 5.0042 | F37: 0.8143 | G37: 48.034 | H37: 0.048323 | I37: =G37/E37 -> 9.5987371 | J37: =F37*E37 -> 4.0749201 | K37: =H37*G37 -> 2.321147 | L37: =J37-K37 -> 1.7537731 | M37: =K37/J37 -> 0.5696178 | N37: 1000 | O37: =C37&"_"&TEXT(B37,"0,####")&"_"&TEXT(ROUND(E37,3),"#,#")&"_"&TEXT(G37,"0")&"_"&TEXT(ROUND(K37,1),"0,#") -> dcm_0,2291_5,_48_2,3 | P37: passiver wdst
B38: 0.3711 | C38: dcm | D38: =TEXT(ROUND(E38,3),"#,#")&"_"&TEXT(G38,"0") -> 5,_48 | E38: 5.004 | F38: 1.778 | G38: 48.02 | H38: 0.10397 | I38: =G38/E38 -> 9.5963229 | J38: =F38*E38 -> 8.897112 | K38: =H38*G38 -> 4.9926394 | L38: =J38-K38 -> 3.9044726 | M38: =K38/J38 -> 0.56115281 | N38: 460
B39: 0.4453 | C39: ccm | D39: =TEXT(ROUND(E39,3),"#,#")&"_"&TEXT(G39,"0") -> 5,_48 | E39: 5.0097 | F39: 2.4888 | G39: 48.062 | H39: 0.15589 | I39: =G39/E39 -> 9.5937881 | J39: =F39*E39 -> 12.468141 | K39: =H39*G39 -> 7.4923852 | L39: =J39-K39 -> 4.9757562 | M39: =K39/J39 -> 0.60092238 | N39: 307
B40: 0.447 | C40: ccm | D40: =TEXT(ROUND(E40,3),"#,#")&"_"&TEXT(G40,"0") -> 5,_48 | E40: 5.003 | F40: 3.2254 | G40: 48.057 | H40: 0.20777 | I40: =G40/E40 -> 9.6056366 | J40: =F40*E40 -> 16.136676 | K40: =H40*G40 -> 9.9848029 | L40: =J40-K40 -> 6.1518733 | M40: =K40/J40 -> 0.61876453 | N40: 230
B41: 0.4504 | C41: ccm | D41: =TEXT(ROUND(E41,3),"#,#")&"_"&TEXT(G41,"0") -> 5,_48 | E41: 5.002 | F41: 6.083 | G41: 48.01 | H41: 0.39903 | I41: =G41/E41 -> 9.5981607 | J41: =F41*E41 -> 30.427166 | K41: =H41*G41 -> 19.15743 | L41: =J41-K41 -> 11.269736 | M41: =K41/J41 -> 0.62961599 | N41: 120 | O41: =C41&"_"&TEXT(B41,"0,####")&"_"&TEXT(ROUND(E41,3),"#,#")&"_"&TEXT(G41,"0")&"_"&TEXT(ROUND(K41,1),"0,#") -> ccm_0,4504_5,_48_19,2
B43: 0.0493 | C43: dcm | D43: =TEXT(ROUND(E43,3),"#,#")&"_"&TEXT(G43,"0") -> 12,_24 | E43: 12.005 | F43: 0.07325 | G43: 24.023 | H43: 0.0242 | I43: =G43/E43 -> 2.0010829 | J43: =F43*E43 -> 0.87936625 | K43: =H43*G43 -> 0.5813566 | L43: =J43-K43 -> 0.29800965 | M43: =K43/J43 -> 0.66110861 | N43: 1000 | O43: =C43&"_"&TEXT(B43,"0,####")&"_"&TEXT(ROUND(E43,3),"#,#")&"_"&TEXT(G43,"0")&"_"&TEXT(ROUND(K43,1),"0,#") -> dcm_0,0493_12,_24_0,6 | P43: passiver wdst
B44: 0.069 | C44: dcm | D44: =TEXT(ROUND(E44,3),"#,#")&"_"&TEXT(G44,"0") -> 12,_24 | E44: 12.0028 | F44: 0.143 | G44: 24.05 | H44: 0.05985 | I44: =G44/E44 -> 2.0036991 | J44: =F44*E44 -> 1.7164004 | K44: =H44*G44 -> 1.4393925 | L44: =J44-K44 -> 0.2770079 | M44: =K44/J44 -> 0.83861114 | N44: 400
B45: 0.1078 | C45: dcm | D45: =TEXT(ROUND(E45,3),"#,#")&"_"&TEXT(G45,"0") -> 12,_24 | E45: 12.001 | F45: 0.2387 | G45: 24.009 | H45: 0.10021 | I45: =G45/E45 -> 2.0005833 | J45: =F45*E45 -> 2.8646387 | K45: =H45*G45 -> 2.4059419 | L45: =J45-K45 -> 0.45869681 | M45: =K45/J45 -> 0.83987621 | N45: 240
B46: 0.1614 | C46: dcm | D46: =TEXT(ROUND(E46,3),"#,#")&"_"&TEXT(G46,"0") -> 12,_24 | E46: 12.002 | F46: 0.47774 | G46: 24.023 | H46: 0.20872 | I46: =G46/E46 -> 2.0015831 | J46: =F46*E46 -> 5.7338355 | K46: =H46*G46 -> 5.0140806 | L46: =J46-K46 -> 0.71975492 | M46: =K46/J46 -> 0.87447235 | N46: 115
B47: 0.2077 | C47: dcm | D47: =TEXT(ROUND(E47,3),"#,#")&"_"&TEXT(G47,"0") -> 12,_24 | E47: 12.0078 | F47: 0.72054 | G47: 24.0185 | H47: 0.31572 | I47: =G47/E47 -> 2.0002415 | J47: =F47*E47 -> 8.6521002 | K47: =H47*G47 -> 7.5831208 | L47: =J47-K47 -> 1.0689794 | M47: =K47/J47 -> 0.87644857 | N47: 76 | O47: =C47&"_"&TEXT(B47,"0,####")&"_"&TEXT(ROUND(E47,3),"#,#")&"_"&TEXT(G47,"0")&"_"&TEXT(ROUND(K47,1),"0,#") -> dcm_0,2077_12,_24_7,6
...

Sheet Bildverzeichnis
A2: Oszi-Bild | B2: Thermo-Bild | C2: Ref [M_d_Vin_Vout_Pout] | D2: Ch1 | E2: CH2 | F2: CH3 | G2: CH4 | H2: comment
A3: tek00000 | B3: HM20260313095043 | C3: =Wirkungsgradkurven!O18 -> ccm_0,4423_3,3_24_7,5 | D3: SIG1 | E3: SIG2 | F3: IL11 | G3: IL21
A4: tek00001 | B4: HM20260313101050 | C4: =Wirkungsgradkurven!O20 -> ccm_0,447_3,3_24_11,8 | D4: SIG1 | E4: SIG2 | F4: IL11 | G4: IL21
A5: tek00003 | B5: - | C5: =Wirkungsgradkurven!O22 -> dcm_0,125_5,_12_0,5 | D5: SIG1 | E5: SIG2 | F5: IL11 | G5: IL21 | H5: dcm, schwierige Messdatenerfassung aufgrund von leichtem schwingen im System
A6: tek00004 | B6: - | C6: =Wirkungsgradkurven!O15 -> dcm_0,272_3,3_24_1,2 | D6: SIG1 | E6: SIG2 | F6: IL11 | G6: IL21
A7: tek00005 | B7: - | C7: =Wirkungsgradkurven!O32 -> ccm_0,401_5,_24_5, | D7: SIG1 | E7: SIG2 | F7: IL11 | G7: IL21
A8: tek00006 | B8: - | C8: =Wirkungsgradkurven!O41 -> ccm_0,4504_5,_48_19,2 | D8: SIG1 | E8: SIG2 | F8: IL11 | G8: IL21 | H8: ccm, strombegrenzt durch Netzteil Ausgangsstrom
A9: tek00007 | B9: - | C9: =Wirkungsgradkurven!O37 -> dcm_0,2291_5,_48_2,3 | D9: SIG1 | E9: SIG2 | F9: IL11 | G9: IL21
A10: tek00008 | B10: - | C10: =Wirkungsgradkurven!O43 -> dcm_0,0493_12,_24_0,6 | D10: SIG1 | E10: SIG2 | F10: IL11 | G10: IL21
A11: tek00009 | B11: - | C11: =Wirkungsgradkurven!O47 -> dcm_0,2077_12,_24_7,6 | D11: SIG1 | E11: SIG2 | F11: IL11 | G11: IL21
A12: tek00010 | B12: HM20260313133236 | C12: =Wirkungsgradkurven!O53 -> ccm_0,2686_12,_24_63,4 | D12: SIG1 | E12: SIG2 | F12: IL11 | G12: IL21 | H12: ccm, strombegrenzt durch Netzteil Ausgangsstrom
A13: tek00011 | B13: HM20260313144957, HM20260313145028 | C13: =Wirkungsgradkurven!O72 -> ccm_0,2538_24,_48_133,5 | D13: SIG1 | E13: SIG2 | F13: IL11 | G13: IL21 | H13: ccm, strombegrenzt durch Netzteil Ausgangsstrom
A14: - | B14: Ordner: | C14: =Wirkungsgradkurven!O50 -> ccm_0,263_12,_24_28,7 | D14: - | E14: - | F14: - | G14: - | H14: Ref Messung für Stationäre Messungen
A15: - | B15: Ordner: | C15: =Wirkungsgradkurven!O70 -> ccm_0,253_24,_48_93,3 | D15: - | E15: - | F15: - | G15: - | H15: Ref Messung für Stationäre Messungen

Sheet Messmittel
B2: Gerät | C2: Art | D2: Verwendung | E2: Anzahl
B3: Tektronix AFG3022B | C3: Funktionsgenerator | D3: Schalter-Ansteuersignal | E3: 1
B4: Tektronix MSO 3034 | C4: Digitales Oszilloskop | D4: Messsignale im Zeitbereich | E4: 1
B5: GWINSTEK SPD-3606 | C5: Labor Netzteil | D5: Versorgung DCDC, Treiber | E5: 1
B6: Tektronix DMM 4040 6-1/2 | C6: Digitales Multimeter | D6: Vout,Iout, Vin, Iin RMS Messung | E6: 4
B7: GOSSEN METRAWATT 32EL300R30 | C7: Elektronische Last | D7: Stellbare Ohm'sche Last | E7: 1
B8: HIKMICRO HM-TP42-3AQF/W-Pocket2 | C8: Thermo Kamera | D8: Halbleiter Temperaturüberwachung | E8: 1
B9: Passiver Leistungswiderstand mit Kühlkörper | C9: 1k Ohm Leistungswiderstand | D9: Ohmsche Last | E9: 1
B10: TCP202 AC/DC Current Probe | C10: Strommesszange | D10: Isolierte Strommessung im Zeitbereich | E10: 2

Sheet Simulationsvergleich
A2: Arbeitspunkt Betrachtung | B2: d [\%] | C2: U1 [V] | D2: U2 [V] | E2: P1[W] | F2: P2[W] | G2: η [\%]
A3: Simulation 12V\_24V\_20$\Omega$ | B3: 26.5 | C3: 12 | D3: 24.08 | E3: 31.55 | F3: 29 | G3: 91.9
A4: Simulation 24V\_48V\_25$\Omega$ | B4: 25.8 | C4: 24 | D4: 47.96 | E4: 97.04 | F4: 92 | G4: 94.8
A5: Messung 12V\_24V\_20$\Omega$ | B5: 26.3 | C5: 12.0039 | D5: 24.07 | E5: 32.254359 | F5: 28.699624 | G5: 88.979054
A6: Messung 24V\_48V\_25$\Omega$ | B6: 25.3 | C6: 24.0136 | D6: 48.113 | E6: 101.39743 | F6: 93.324786 | G6: 92.038615
