Workbook

Sheet Uebersetzung_ccm
B1: Berechnet für Continuous Conduction Mode
B4: d und U1 werden nährungsweise Konstant gehalten / jeder erste Wert in einem Messreihen block ist nahe am "Anfang des CCM" => critical conduction mode aufgenommen
B5: Thermische EInschwingzeit: 2-5 min | N5: SerienWdst des Kabels ist hier nicht mit erfasst
B6: Ansteuerung | C6: Ü_ideal | D6: Messung | E6: Messwerte | I6: Rechenwerte | N6: Stellwert
B7: d | C7: Ü | D7: Name | E7: U1 [V] | F7: I1 [A] | G7: U2 [V] | H7: I2 [A] | I7: U2/U1 | J7: P1 [W] | K7: P2 [W] | L7: Pdiff [W] | M7: P2/P1 | N7: R_L [Ω]
B8: 0.05 | C8: =1/(1-2*B8) -> 1.1111111 | D8: =TEXT(ROUND(E8,3),"#,#")&"_"&TEXT(B8,"0,##") -> 3,3_0,05 | E8: 3.3049 | F8: 0.4427 | G8: 2.7922 | H8: 0.3875 | I8: =G8/E8 -> 0.84486671 | J8: =F8*E8 -> 1.4630792 | K8: =H8*G8 -> 1.0819775 | L8: =J8-K8 -> 0.38110173 | M8: =K8/J8 -> 0.73952078 | N8: 7
B9: 0.05 | C9: =1/(1-2*B9) -> 1.1111111 | D9: =TEXT(ROUND(E9,3),"#,#")&"_"&TEXT(B9,"0,##") -> 3,3_0,05 | E9: 3.3048 | F9: 1.265 | G9: 2.623 | H9: 1.1205 | I9: =G9/E9 -> 0.79369402 | J9: =F9*E9 -> 4.180572 | K9: =H9*G9 -> 2.9390715 | L9: =J9-K9 -> 1.2415005 | M9: =K9/J9 -> 0.70303095 | N9: 2
B10: 0.05 | C10: =1/(1-2*B10) -> 1.1111111 | D10: =TEXT(ROUND(E10,3),"#,#")&"_"&TEXT(B10,"0,##") -> 3,3_0,05 | E10: 3.297 | F10: 1.6953 | G10: 2.5495 | H10: 1.5014 | I10: =G10/E10 -> 0.77327874 | J10: =F10*E10 -> 5.5894041 | K10: =H10*G10 -> 3.8278193 | L10: =J10-K10 -> 1.7615848 | M10: =K10/J10 -> 0.68483495 | N10: 1.4
B11: 0.05 | C11: =1/(1-2*B11) -> 1.1111111 | D11: =TEXT(ROUND(E11,3),"#,#")&"_"&TEXT(B11,"0,##") -> 3,3_0,05 | E11: 3.3013 | F11: 2.6088 | G11: 2.419 | H11: 2.3135 | I11: =G11/E11 -> 0.73274165 | J11: =F11*E11 -> 8.6124314 | K11: =H11*G11 -> 5.5963565 | L11: =J11-K11 -> 3.0160749 | M11: =K11/J11 -> 0.64979983 | N11: 0.8
B12: 0.05 | C12: =1/(1-2*B12) -> 1.1111111 | D12: =TEXT(ROUND(E12,3),"#,#")&"_"&TEXT(B12,"0,##") -> 3,3_0,05 | E12: 3.3056 | F12: 3.6237 | G12: 2.272 | H12: 3.21926 | I12: =G12/E12 -> 0.68731849 | J12: =F12*E12 -> 11.978503 | K12: =H12*G12 -> 7.3141587 | L12: =J12-K12 -> 4.664344 | M12: =K12/J12 -> 0.61060709 | N12: 0.5
B14: 0.05 | C14: =1/(1-2*B14) -> 1.1111111 | D14: =TEXT(ROUND(E14,3),"#")&"_"&TEXT(B14,"0,##") -> 5_0,05 | E14: 5.016 | F14: 0.22588 | G14: 4.8673 | H14: 0.19325 | I14: =G14/E14 -> 0.97035486 | J14: =F14*E14 -> 1.1330141 | K14: =H14*G14 -> 0.94060573 | L14: =J14-K14 -> 0.19240835 | M14: =K14/J14 -> 0.83018008 | N14: 25
B15: 0.05 | C15: =1/(1-2*B15) -> 1.1111111 | D15: =TEXT(ROUND(E15,3),"#")&"_"&TEXT(B15,"0,##") -> 5_0,05 | E15: 5.001 | F15: 0.52878 | G15: 4.704 | H15: 0.4616 | I15: =G15/E15 -> 0.94061188 | J15: =F15*E15 -> 2.6444288 | K15: =H15*G15 -> 2.1713664 | L15: =J15-K15 -> 0.47306238 | M15: =K15/J15 -> 0.82110981 | N15: 10
B16: 0.05 | C16: =1/(1-2*B16) -> 1.1111111 | D16: =TEXT(ROUND(E16,3),"#")&"_"&TEXT(B16,"0,##") -> 5_0,05 | E16: 5.0255 | F16: 1.0136 | G16: 4.6087 | H16: 0.89187 | I16: =G16/E16 -> 0.91706298 | J16: =F16*E16 -> 5.0938468 | K16: =H16*G16 -> 4.1103613 | L16: =J16-K16 -> 0.98348553 | M16: =K16/J16 -> 0.80692676 | N16: 5
B17: 0.05 | C17: =1/(1-2*B17) -> 1.1111111 | D17: =TEXT(ROUND(E17,3),"#")&"_"&TEXT(B17,"0,##") -> 5_0,05 | E17: 5.0235 | F17: 1.40218 | G17: 4.5221 | H17: 1.2369 | I17: =G17/E17 -> 0.90018911 | J17: =F17*E17 -> 7.0438512 | K17: =H17*G17 -> 5.5933855 | L17: =J17-K17 -> 1.4504657 | M17: =K17/J17 -> 0.79408058 | N17: 3.5
B18: 0.05 | C18: =1/(1-2*B18) -> 1.1111111 | D18: =TEXT(ROUND(E18,3),"#")&"_"&TEXT(B18,"0,##") -> 5_0,05 | E18: 5.0251 | F18: 1.89888 | G18: 4.4476 | H18: 1.67768 | I18: =G18/E18 -> 0.88507691 | J18: =F18*E18 -> 9.5420619 | K18: =H18*G18 -> 7.4616496 | L18: =J18-K18 -> 2.0804123 | M18: =K18/J18 -> 0.78197455 | N18: 2.5
B19: 0.05 | C19: =1/(1-2*B19) -> 1.1111111 | D19: =TEXT(ROUND(E19,3),"#")&"_"&TEXT(B19,"0,##") -> 5_0,05 | E19: 5.0303 | F19: 4.0588 | G19: 4.1147 | H19: 3.5956 | I19: =G19/E19 -> 0.81798302 | J19: =F19*E19 -> 20.416982 | K19: =H19*G19 -> 14.794815 | L19: =J19-K19 -> 5.6221663 | M19: =K19/J19 -> 0.72463284 | N19: 1
B21: 0.05 | C21: =1/(1-2*B21) -> 1.1111111 | D21: =TEXT(ROUND(E21,3),"#")&"_"&TEXT(B21,"0,##") -> 9_0,05 | E21: 9.0446 | F21: 0.15554 | G21: 9.6345 | H21: 0.127925 | I21: =G21/E21 -> 1.0652212 | J21: =F21*E21 -> 1.4067971 | K21: =H21*G21 -> 1.2324934 | L21: =J21-K21 -> 0.17430367 | M21: =K21/J21 -> 0.87609892 | N21: 75
B22: 0.05 | C22: =1/(1-2*B22) -> 1.1111111 | D22: =TEXT(ROUND(E22,3),"#")&"_"&TEXT(B22,"0,##") -> 9_0,05 | E22: 9.0177 | F22: 0.3627 | G22: 9.3816 | H22: 0.3105 | I22: =G22/E22 -> 1.040354 | J22: =F22*E22 -> 3.2707198 | K22: =H22*G22 -> 2.9129868 | L22: =J22-K22 -> 0.35773299 | M22: =K22/J22 -> 0.89062561 | N22: 30
B23: 0.05 | C23: =1/(1-2*B23) -> 1.1111111 | D23: =TEXT(ROUND(E23,3),"#")&"_"&TEXT(B23,"0,##") -> 9_0,05 | E23: 9.0133 | F23: 0.69977 | G23: 9.2208 | H23: 0.609 | I23: =G23/E23 -> 1.0230215 | J23: =F23*E23 -> 6.3072369 | K23: =H23*G23 -> 5.6154672 | L23: =J23-K23 -> 0.69176974 | M23: =K23/J23 -> 0.89032127 | N23: 15
B24: 0.05 | C24: =1/(1-2*B24) -> 1.1111111 | D24: =TEXT(ROUND(E24,3),"#")&"_"&TEXT(B24,"0,##") -> 9_0,05 | E24: 9.0545 | F24: 1.98881 | G24: 8.9909 | H24: 1.7514 | I24: =G24/E24 -> 0.99297587 | J24: =F24*E24 -> 18.00768 | K24: =H24*G24 -> 15.746662 | L24: =J24-K24 -> 2.2610179 | M24: =K24/J24 -> 0.87444147 | N24: 5
B25: 0.05 | C25: =1/(1-2*B25) -> 1.1111111 | D25: =TEXT(ROUND(E25,3),"#")&"_"&TEXT(B25,"0,##") -> 9_0,05 | E25: 9.0116 | F25: 3.1626 | G25: 8.7489 | H25: 2.7907 | I25: =G25/E25 -> 0.97084868 | J25: =F25*E25 -> 28.500086 | K25: =H25*G25 -> 24.415555 | L25: =J25-K25 -> 4.0845309 | M25: =K25/J25 -> 0.85668356 | N25: 3
B26: 0.05 | C26: =1/(1-2*B26) -> 1.1111111 | D26: =TEXT(ROUND(E26,3),"#")&"_"&TEXT(B26,"0,##") -> 9_0,05 | E26: 9.0385 | F26: 4.54 | G26: 8.59 | H26: 4.0236 | I26: =G26/E26 -> 0.95037893 | J26: =F26*E26 -> 41.03479 | K26: =H26*G26 -> 34.562724 | L26: =J26-K26 -> 6.472066 | M26: =K26/J26 -> 0.84227856 | N26: 2
... B38: 0.05 | C38: =1/(1-2*B38) -> 1.1111111 | D38: =TEXT(ROUND(E38,3),"#")&"_"&TEXT(B38,"0,##") -> 24_0,05 | E38: 24.0347 | F38: 2.9163 | G38: 25.83 | H38: 2.5558 | I38: =G38/E38 -> 1.0746962 | J38: =F38*E38 -> 70.092396 | K38: =H38*G38 -> 66.016314 | L38: =J38-K38 -> 4.0760816 | M38: =K38/J38 -> 0.94184702 | N38: 10
B40: 0.1 | C40: =1/(1-2*B40) -> 1.25 | D40: =TEXT(ROUND(E40,3),"#,#")&"_"&TEXT(B40,"0,##") -> 3,3_0,1 | E40: 3.3028 | F40: 0.1488 | G40: 3.376 | H40: 0.11157 | I40: =G40/E40 -> 1.022163 | J40: =F40*E40 -> 0.49145664 | K40: =H40*G40 -> 0.37666032 | L40: =J40-K40 -> 0.11479632 | M40: =K40/J40 -> 0.76641618 | N40: 30
B41: 0.1 | C41: =1/(1-2*B41) -> 1.25 | D41: =TEXT(ROUND(E41,3),"#,#")&"_"&TEXT(B41,"0,##") -> 3,3_0,1 | E41: 3.30533 | F41: 0.2827 | G41: 3.27 | H41: 0.21662 | I41: =G41/E41 -> 0.9893112 | J41: =F41*E41 -> 0.93441679 | K41: =H41*G41 -> 0.7083474 | L41: =J41-K41 -> 0.22606939 | M41: =K41/J41 -> 0.75806365 | N41: 15
B42: 0.1 | C42: =1/(1-2*B42) -> 1.25 | D42: =TEXT(ROUND(E42,3),"#,#")&"_"&TEXT(B42,"0,##") -> 3,3_0,1 | E42: 3.3004 | F42: 0.77426 | G42: 3.0951 | H42: 0.60363 | I42: =G42/E42 -> 0.93779542 | J42: =F42*E42 -> 2.5553677 | K42: =H42*G42 -> 1.8682952 | L42: =J42-K42 -> 0.68707249 | M42: =K42/J42 -> 0.73112578 | N42: 5
B43: 0.1 | C43: =1/(1-2*B43) -> 1.25 | D43: =TEXT(ROUND(E43,3),"#,#")&"_"&TEXT(B43,"0,##") -> 3,3_0,1 | E43: 3.3036 | F43: 2.9702 | G43: 2.639 | H43: 2.338 | I43: =G43/E43 -> 0.79882552 | J43: =F43*E43 -> 9.8123527 | K43: =H43*G43 -> 6.169982 | L43: =J43-K43 -> 3.6423707 | M43: =K43/J43 -> 0.62879741 | N43: 1
B44: 0.1 | C44: =1/(1-2*B44) -> 1.25 | D44: =TEXT(ROUND(E44,3),"#,#")&"_"&TEXT(B44,"0,##") -> 3,3_0,1 | E44: 3.3002 | F44: 4.738 | G44: 2.3685 | H44: 3.74 | I44: =G44/E44 -> 0.71768378 | J44: =F44*E44 -> 15.636348 | K44: =H44*G44 -> 8.85819 | L44: =J44-K44 -> 6.7781576 | M44: =K44/J44 -> 0.56651273 | N44: 0.5
B46: 0.1 | C46: =1/(1-2*B46) -> 1.25 | D46: =TEXT(ROUND(E46,3),"#")&"_"&TEXT(B46,"0,##") -> 5_0,1 | E46: 5.0048 | F46: 0.28647 | G46: 5.4734 | H46: 0.2174 | I46: =G46/E46 -> 1.0936301 | J46: =F46*E46 -> 1.4337251 | K46: =H46*G46 -> 1.1899172 | L46: =J46-K46 -> 0.2438079 | M46: =K46/J46 -> 0.82994794 | N46: 25
B47: 0.1 | C47: =1/(1-2*B47) -> 1.25 | D47: =TEXT(ROUND(E47,3),"#")&"_"&TEXT(B47,"0,##") -> 5_0,1 | E47: 5.003 | F47: 0.67462 | G47: 5.305 | H47: 0.52247 | I47: =G47/E47 -> 1.0603638 | J47: =F47*E47 -> 3.3751239 | K47: =H47*G47 -> 2.7717033 | L47: =J47-K47 -> 0.60342051 | M47: =K47/J47 -> 0.8212153 | N47: 10
B48: 0.1 | C48: =1/(1-2*B48) -> 1.25 | D48: =TEXT(ROUND(E48,3),"#")&"_"&TEXT(B48,"0,##") -> 5_0,1 | E48: 5.009 | F48: 1.28576 | G48: 5.1547 | H48: 1.00352 | I48: =G48/E48 -> 1.0290876 | J48: =F48*E48 -> 6.4403718 | K48: =H48*G48 -> 5.1728445 | L48: =J48-K48 -> 1.2675273 | M48: =K48/J48 -> 0.80319035 | N48: 5
B49: 0.1 | C49: =1/(1-2*B49) -> 1.25 | D49: =TEXT(ROUND(E49,3),"#")&"_"&TEXT(B49,"0,##") -> 5_0,1 | E49: 5.0004 | F49: 2.3928 | G49: 4.9185 | H49: 1.8747 | I49: =G49/E49 -> 0.98362131 | J49: =F49*E49 -> 11.964957 | K49: =H49*G49 -> 9.220712 | L49: =J49-K49 -> 2.7442452 | M49: =K49/J49 -> 0.77064313 | N49: 2.5
B50: 0.1 | C50: =1/(1-2*B50) -> 1.25 | D50: =TEXT(ROUND(E50,3),"#")&"_"&TEXT(B50,"0,##") -> 5_0,1 | E50: 5.026 | F50: 5.05 | G50: 4.4999 | H50: 3.9734 | I50: =G50/E50 -> 0.89532431 | J50: =F50*E50 -> 25.3813 | K50: =H50*G50 -> 17.879903 | L50: =J50-K50 -> 7.5013973 | M50: =K50/J50 -> 0.70445181 | N50: 1
B52: 0.1 | C52: =1/(1-2*B52) -> 1.25 | D52: =TEXT(ROUND(E52,3),"#")&"_"&TEXT(B52,"0,##") -> 9_0,1 | E52: 9 | F52: 0.28489 | G52: 10.675 | H52: 0.21225 | I52: =G52/E52 -> 1.1861111 | J52: =F52*E52 -> 2.56401 | K52: =H52*G52 -> 2.2657687 | L52: =J52-K52 -> 0.29824125 | M52: =K52/J52 -> 0.88368171 | N52: 50
B53: 0.1 | C53: =1/(1-2*B53) -> 1.25 | D53: =TEXT(ROUND(E53,3),"#")&"_"&TEXT(B53,"0,##") -> 9_0,1 | E53: 9.0055 | F53: 0.54806 | G53: 10.5132 | H53: 0.41836 | I53: =G53/E53 -> 1.1674199 | J53: =F53*E53 -> 4.9355543 | K53: =H53*G53 -> 4.3983024 | L53: =J53-K53 -> 0.53725198 | M53: =K53/J53 -> 0.89114658 | N53: 25
B54: 0.1 | C54: =1/(1-2*B54) -> 1.25 | D54: =TEXT(ROUND(E54,3),"#")&"_"&TEXT(B54,"0,##") -> 9_0,1 | E54: 9.048 | F54: 1.31283 | G54: 10.323 | H54: 1.01898 | I54: =G54/E54 -> 1.1409151 | J54: =F54*E54 -> 11.878486 | K54: =H54*G54 -> 10.518931 | L54: =J54-K54 -> 1.3595553 | M54: =K54/J54 -> 0.88554473 | N54: 10
B55: 0.1 | C55: =1/(1-2*B55) -> 1.25 | D55: =TEXT(ROUND(E55,3),"#")&"_"&TEXT(B55,"0,##") -> 9_0,1 | E55: 9.0316 | F55: 2.5103 | G55: 10.048 | H55: 1.9594 | I55: =G55/E55 -> 1.1125382 | J55: =F55*E55 -> 22.672025 | K55: =H55*G55 -> 19.688051 | L55: =J55-K55 -> 2.9839743 | M55: =K55/J55 -> 0.86838519 | N55: 5
B56: 0.1 | C56: =1/(1-2*B56) -> 1.25 | D56: =TEXT(ROUND(E56,3),"#")&"_"&TEXT(B56,"0,##") -> 9_0,1 | E56: 9.0035 | F56: 3.97737 | G56: 9.7479 | H56: 3.1105 | I56: =G56/E56 -> 1.082679 | J56: =F56*E56 -> 35.810251 | K56: =H56*G56 -> 30.320843 | L56: =J56-K56 -> 5.4894078 | M56: =K56/J56 -> 0.84670848 | N56: 3
B57: 0.1 | C57: =1/(1-2*B57) -> 1.25 | D57: =TEXT(ROUND(E57,3),"#")&"_"&TEXT(B57,"0,##") -> 9_0,1 | E57: 9.0327 | F57: 4.6868 | G57: 9.682 | H57: 3.6669 | I57: =G57/E57 -> 1.0718833 | J57: =F57*E57 -> 42.334458 | K57: =H57*G57 -> 35.502926 | L57: =J57-K57 -> 6.8315326 | M57: =K57/J57 -> 0.8386295 | N57: 2.5
B59: 0.1 | C59: =1/(1-2*B59) -> 1.25 | D59: =TEXT(ROUND(E59,3),"#")&"_"&TEXT(B59,"0,##") -> 12_0,1 | E59: 12.0345 | F59: 0.3865 | G59: 14.5235 | H59: 0.28925 | I59: =G59/E59 -> 1.2068221 | J59: =F59*E59 -> 4.6513342 | K59: =H59*G59 -> 4.2009224 | L59: =J59-K59 -> 0.45041187 | M59: =K59/J59 -> 0.90316502 | N59: 50
...

Sheet Wirkungsgradkurven
B1: Wirkungsgradkurven
B4: U1 und U2 werden nährungsweise Konstant gehalten, Converter im dcm und ccm Betrieb je nach Last
B5: Thermische EInschwingzeit: 2-5 min | N5: SerienWdst des Kabels ist hier nicht mit erfasst
B6: Ansteuerung | C6: Betriebszustand | D6: Messung | E6: Messwerte | I6: Rechenwerte | N6: Stellwert | O6: Referenz [M_d_Vin_Vout_Pout]
B7: d | C7: M | D7: Name | E7: U1 [V] | F7: I1 [A] | G7: U2 [V] | H7: I2 [A] | I7: U2/U1 | J7: P1 [W] | K7: P2 [W] | L7: Pdiff [W] | M7: P2/P1 | N7: R_L [Ω]
B8: 0.3 | C8: dcm | D8: =TEXT(ROUND(E8,3),"#,#")&"_"&TEXT(G8,"0") -> 3,3_12 | E8: 3.3047 | F8: 0.43557 | G8: 12.045 | H8: 0.08339 | I8: =G8/E8 -> 3.6448089 | J8: =F8*E8 -> 1.4394282 | K8: =H8*G8 -> 1.0044325 | L8: =J8-K8 -> 0.43499563 | M8: =K8/J8 -> 0.6977997 | N8: 144
B9: 0.383 | C9: ccm | D9: =TEXT(ROUND(E9,3),"#,#")&"_"&TEXT(G9,"0") -> 3,3_12 | E9: 3.3044 | F9: 1.0506 | G9: 12.1 | H9: 0.20949 | I9: =G9/E9 -> 3.6617843 | J9: =F9*E9 -> 3.4716026 | K9: =H9*G9 -> 2.534829 | L9: =J9-K9 -> 0.93677364 | M9: =K9/J9 -> 0.73016104 | N9: 57.6
B10: 0.3885 | C10: ccm | D10: =TEXT(ROUND(E10,3),"#,#")&"_"&TEXT(G10,"0") -> 3,3_12 | E10: 3.306 | F10: 2.11661 | G10: 12.05 | H10: 0.41756 | I10: =G10/E10 -> 3.6448881 | J10: =F10*E10 -> 6.9975127 | K10: =H10*G10 -> 5.031598 | L10: =J10-K10 -> 1.9659147 | M10: =K10/J10 -> 0.71905522 | N10: 28.8
B11: 0.3955 | C11: ccm | D11: =TEXT(ROUND(E11,3),"#,#")&"_"&TEXT(G11,"0") -> 3,3_12 | E11: 3.302 | F11: 3.3538 | G11: 12.052 | H11: 0.6257 | I11: =G11/E11 -> 3.6499091 | J11: =F11*E11 -> 11.074248 | K11: =H11*G11 -> 7.5409364 | L11: =J11-K11 -> 3.5333112 | M11: =K11/J11 -> 0.68094345 | N11: 19.2
B12: 0.4015 | C12: ccm | D12: =TEXT(ROUND(E12,3),"#,#")&"_"&TEXT(G12,"0") -> 3,3_12 | E12: 3.303 | F12: 4.711 | G12: 12.024 | H12: 0.83157 | I12: =G12/E12 -> 3.640327 | J12: =F12*E12 -> 15.560433 | K12: =H12*G12 -> 9.9987977 | L12: =J12-K12 -> 5.5616353 | M12: =K12/J12 -> 0.64257837 | N12: 14.4
B13: 0.404 | C13: ccm | D13: =TEXT(ROUND(E13,3),"#,#")&"_"&TEXT(G13,"0") -> 3,3_12 | E13: 3.304 | F13: 5.823 | G13: 12.048 | H13: 0.9977 | I13: =G13/E13 -> 3.6464891 | J13: =F13*E13 -> 19.239192 | K13: =H13*G13 -> 12.02029 | L13: =J13-K13 -> 7.2189024 | M13: =K13/J13 -> 0.62478141 | N13: 12
B15: 0.273 | C15: dcm | D15: =TEXT(ROUND(E15,3),"#,#")&"_"&TEXT(G15,"0") -> 3,3_24 | E15: 3.303 | F15: 0.6016 | G15: 24.085 | H15: 0.04814 | I15: =G15/E15 -> 7.2918559 | J15: =F15*E15 -> 1.9870848 | K15: =H15*G15 -> 1.1594519 | L15: =J15-K15 -> 0.8276329 | M15: =K15/J15 -> 0.58349392 | N15: 500 | O15: =C15&"_"&TEXT(B15,"0,####")&"_"&TEXT(ROUND(E15,3),"#,#")&"_"&TEXT(G15,"0")&"_"&TEXT(ROUND(K15,1),"0,##") -> dcm_0,273_3,3_24_1,2
B16: 0.436 | C16: ccm | D16: =TEXT(ROUND(E16,3),"#,#")&"_"&TEXT(G16,"0") -> 3,3_24 | E16: 3.305 | F16: 1.268 | G16: 24.145 | H16: 0.1053 | I16: =G16/E16 -> 7.3055976 | J16: =F16*E16 -> 4.19074 | K16: =H16*G16 -> 2.5424685 | L16: =J16-K16 -> 1.6482715 | M16: =K16/J16 -> 0.60668724 | N16: 230
B17: 0.4395 | C17: ccm | D17: =TEXT(ROUND(E17,3),"#,#")&"_"&TEXT(G17,"0") -> 3,3_24 | E17: 3.304 | F17: 2.383 | G17: 24.04 | H17: 0.20924 | I17: =G17/E17 -> 7.2760291 | J17: =F17*E17 -> 7.873432 | K17: =H17*G17 -> 5.0301296 | L17: =J17-K17 -> 2.8433024 | M17: =K17/J17 -> 0.63887382 | N17: 115
B18: 0.4425 | C18: ccm | D18: =TEXT(ROUND(E18,3),"#,#")&"_"&TEXT(G18,"0") -> 3,3_24 | E18: 3.306 | F18: 3.6506 | G18: 24.01 | H18: 0.31527 | I18: =G18/E18 -> 7.2625529 | J18: =F18*E18 -> 12.068884 | K18: =H18*G18 -> 7.5696327 | L18: =J18-K18 -> 4.4992509 | M18: =K18/J18 -> 0.6272024 | N18: 76
B19: 0.4453 | C19: ccm | D19: =TEXT(ROUND(E19,3),"#,#")&"_"&TEXT(G19,"0") -> 3,3_24 | E19: 3.3047 | F19: 5.0006 | G19: 24.06 | H19: 0.41422 | I19: =G19/E19 -> 7.2805398 | J19: =F19*E19 -> 16.525483 | K19: =H19*G19 -> 9.9661332 | L19: =J19-K19 -> 6.5593496 | M19: =K19/J19 -> 0.60307667 | N19: 58
B20: 0.4473 | C20: ccm | D20: =TEXT(ROUND(E20,3),"#,#")&"_"&TEXT(G20,"0") -> 3,3_24 | E20: 3.3055 | F20: 6.038 | G20: 24.17 | H20: 0.4828 | I20: =G20/E20 -> 7.3120557 | J20: =F20*E20 -> 19.958609 | K20: =H20*G20 -> 11.669276 | L20: =J20-K20 -> 8.289333 | M20: =K20/J20 -> 0.58467381 | N20: 50
B22: 0.123 | C22: dcm | D22: =TEXT(ROUND(E22,3),"#,#")&"_"&TEXT(G22,"0") -> 5,_12 | E22: 5.00292 | F22: 0.12282 | G22: 12.081 | H22: 0.03993 | I22: =G22/E22 -> 2.4147898 | J22: =F22*E22 -> 0.61445863 | K22: =H22*G22 -> 0.48239433 | L22: =J22-K22 -> 0.1320643 | M22: =K22/J22 -> 0.7850721 | N22: 300 | O22: =C22&"_"&TEXT(B22,"0,####")&"_"&TEXT(ROUND(E22,3),"#,#")&"_"&TEXT(G22,"0")&"_"&TEXT(ROUND(K22,1),"0,##") -> dcm_0,123_5,_12_0,5
B23: 0.185 | C23: dcm | D23: =TEXT(ROUND(E23,3),"#,#")&"_"&TEXT(G23,"0") -> 5,_12 | E23: 5.0054 | F23: 0.2496 | G23: 12.009 | H23: 0.083146 | I23: =G23/E23 -> 2.3992089 | J23: =F23*E23 -> 1.2493478 | K23: =H23*G23 -> 0.99850031 | L23: =J23-K23 -> 0.25084753 | M23: =K23/J23 -> 0.79921723 | N23: 144
B24: 0.3085 | C24: ccm | D24: =TEXT(ROUND(E24,3),"#,#")&"_"&TEXT(G24,"0") -> 5,_12 | E24: 5.0016 | F24: 0.61339 | G24: 12.01 | H24: 0.20703 | I24: =G24/E24 -> 2.4012316 | J24: =F24*E24 -> 3.0679314 | K24: =H24*G24 -> 2.4864303 | L24: =J24-K24 -> 0.58150112 | M24: =K24/J24 -> 0.81045824 | N24: 57.6
B25: 0.3135 | C25: ccm | D25: =TEXT(ROUND(E25,3),"#,#")&"_"&TEXT(G25,"0") -> 5,_12 | E25: 5.005 | F25: 1.21568 | G25: 12.004 | H25: 0.41526 | I25: =G25/E25 -> 2.3984016 | J25: =F25*E25 -> 6.0844784 | K25: =H25*G25 -> 4.984781 | L25: =J25-K25 -> 1.0996974 | M25: =K25/J25 -> 0.81926185 | N25: 28.8
B26: 0.317 | C26: ccm | D26: =TEXT(ROUND(E26,3),"#,#")&"_"&TEXT(G26,"0") -> 5,_12 | E26: 5.008 | F26: 1.8346 | G26: 12.01 | H26: 0.62273 | I26: =G26/E26 -> 2.3981629 | J26: =F26*E26 -> 9.1876768 | K26: =H26*G26 -> 7.4789873 | L26: =J26-K26 -> 1.7086895 | M26: =K26/J26 -> 0.81402377 | N26: 19.2
B27: 0.3206 | C27: ccm | D27: =TEXT(ROUND(E27,3),"#,#")&"_"&TEXT(G27,"0") -> 5,_12 | E27: 5.005 | F27: 2.479 | G27: 12.0125 | H27: 0.8289 | I27: =G27/E27 -> 2.4000999 | J27: =F27*E27 -> 12.407395 | K27: =H27*G27 -> 9.9571612 | L27: =J27-K27 -> 2.4502338 | M27: =K27/J27 -> 0.80251828 | N27: 14.4
B28: 0.338 | C28: ccm | D28: =TEXT(ROUND(E28,3),"#,#")&"_"&TEXT(G28,"0") -> 5,_12 | E28: 5.003 | F28: 5.9295 | G28: 12.36 | H28: 1.8026 | I28: =G28/E28 -> 2.4705177 | J28: =F28*E28 -> 29.665288 | K28: =H28*G28 -> 22.280136 | L28: =J28-K28 -> 7.3851525 | M28: =K28/J28 -> 0.75105071 | N28: 6.6
B30: 0.179 | C30: dcm | D30: =TEXT(ROUND(E30,3),"#,#")&"_"&TEXT(G30,"0") -> 5,_24 | E30: 5.01033 | F30: 0.320216 | G30: 24.023 | H30: 0.048025 | I30: =G30/E30 -> 4.7946942 | J30: =F30*E30 -> 1.6043878 | K30: =H30*G30 -> 1.1537046 | L30: =J30-K30 -> 0.45068326 | M30: =K30/J30 -> 0.71909332 | N30: 500
B31: 0.292 | C31: dcm | D31: =TEXT(ROUND(E31,3),"#,#")&"_"&TEXT(G31,"0") -> 5,_24 | E31: 5.004 | F31: 0.663 | G31: 24.06 | H31: 0.1044 | I31: =G31/E31 -> 4.8081535 | J31: =F31*E31 -> 3.317652 | K31: =H31*G31 -> 2.511864 | L31: =J31-K31 -> 0.805788 | M31: =K31/J31 -> 0.757121 | N31: 230
B32: 0.4004 | C32: ccm | D32: =TEXT(ROUND(E32,3),"#,#")&"_"&TEXT(G32,"0") -> 5,_24 | E32: 5.003 | F32: 1.3392 | G32: 24.007 | H32: 0.20845 | I32: =G32/E32 -> 4.7985209 | J32: =F32*E32 -> 6.7000176 | K32: =H32*G32 -> 5.0042592 | L32: =J32-K32 -> 1.6957584 | M32: =K32/J32 -> 0.74690239 | N32: 115
B33: 0.4028 | C33: ccm | D33: =TEXT(ROUND(E33,3),"#,#")&"_"&TEXT(G33,"0") -> 5,_24 | E33: 5.0043 | F33: 1.9937 | G33: 24.032 | H33: 0.31616 | I33: =G33/E33 -> 4.80227 | J33: =F33*E33 -> 9.9770729 | K33: =H33*G33 -> 7.5979571 | L33: =J33-K33 -> 2.3791158 | M33: =K33/J33 -> 0.76154171 | N33: 76
B34: 0.4038 | C34: ccm | D34: =TEXT(ROUND(E34,3),"#,#")&"_"&TEXT(G34,"0") -> 5,_24 | E34: 5.0145 | F34: 2.5888 | G34: 24.028 | H34: 0.4137 | I34: =G34/E34 -> 4.7917041 | J34: =F34*E34 -> 12.981538 | K34: =H34*G34 -> 9.9403836 | L34: =J34-K34 -> 3.041154 | M34: =K34/J34 -> 0.76573237 | N34: 58
B35: 0.4115 | C35: ccm | D35: =TEXT(ROUND(E35,3),"#,#")&"_"&TEXT(G35,"0") -> 5,_24 | E35: 5.011 | F35: 5.4737 | G35: 24.034 | H35: 0.82755 | I35: =G35/E35 -> 4.7962483 | J35: =F35*E35 -> 27.428711 | K35: =H35*G35 -> 19.889337 | L35: =J35-K35 -> 7.539374 | M35: =K35/J35 -> 0.72512839 | N35: 29
B37: 0.2303 | C37: dcm | D37: =TEXT(ROUND(E37,3),"#,#")&"_"&TEXT(G37,"0") -> 5,_48 | E37: 5 | F37: 0.8177 | G37: 48.015 | H37: 0.0482 | I37: =G37/E37 -> 9.603 | J37: =F37*E37 -> 4.0885 | K37: =H37*G37 -> 2.314323 | L37: =J37-K37 -> 1.774177 | M37: =K37/J37 -> 0.56605674 | N37: 1000 | O37: =C37&"_"&TEXT(B37,"0,####")&"_"&TEXT(ROUND(E37,3),"#,#")&"_"&TEXT(G37,"0")&"_"&TEXT(ROUND(K37,1),"0,##") -> dcm_0,2303_5,_48_2,3 | P37: passiver wdst
B38: 0.3722 | C38: dcm | D38: =TEXT(ROUND(E38,3),"#,#")&"_"&TEXT(G38,"0") -> 5,_48 | E38: 5.0028 | F38: 1.8003 | G38: 48.07 | H38: 0.104 | I38: =G38/E38 -> 9.6086192 | J38: =F38*E38 -> 9.0065408 | K38: =H38*G38 -> 4.99928 | L38: =J38-K38 -> 4.0072608 | M38: =K38/J38 -> 0.55507215 | N38: 460
B39: 0.4465 | C39: ccm | D39: =TEXT(ROUND(E39,3),"#,#")&"_"&TEXT(G39,"0") -> 5,_48 | E39: 5.0025 | F39: 2.531 | G39: 48.077 | H39: 0.15589 | I39: =G39/E39 -> 9.6105947 | J39: =F39*E39 -> 12.661328 | K39: =H39*G39 -> 7.4947235 | L39: =J39-K39 -> 5.166604 | M39: =K39/J39 -> 0.59193821 | N39: 307
B40: 0.4475 | C40: ccm | D40: =TEXT(ROUND(E40,3),"#,#")&"_"&TEXT(G40,"0") -> 5,_48 | E40: 5.007 | F40: 3.242 | G40: 48.07 | H40: 0.2077 | I40: =G40/E40 -> 9.6005592 | J40: =F40*E40 -> 16.232694 | K40: =H40*G40 -> 9.984139 | L40: =J40-K40 -> 6.248555 | M40: =K40/J40 -> 0.61506359 | N40: 230
B41: 0.4508 | C41: ccm | D41: =TEXT(ROUND(E41,3),"#,#")&"_"&TEXT(G41,"0") -> 5,_48 | E41: 5.0052 | F41: 6.083 | G41: 48.03 | H41: 0.39745 | I41: =G41/E41 -> 9.5960201 | J41: =F41*E41 -> 30.446632 | K41: =H41*G41 -> 19.089524 | L41: =J41-K41 -> 11.357108 | M41: =K41/J41 -> 0.6269831 | N41: 120
B43: 0.05 | C43: dcm | D43: =TEXT(ROUND(E43,3),"#,#")&"_"&TEXT(G43,"0") -> 12,_24 | E43: 12.0028 | F43: 0.07333 | G43: 24.033 | H43: 0.02419 | I43: =G43/E43 -> 2.0022828 | J43: =F43*E43 -> 0.88016532 | K43: =H43*G43 -> 0.58135827 | L43: =J43-K43 -> 0.29880705 | M43: =K43/J43 -> 0.66051031 | N43: 1000 | O43: =C43&"_"&TEXT(B43,"0,####")&"_"&TEXT(ROUND(E43,3),"#,#")&"_"&TEXT(G43,"0")&"_"&TEXT(ROUND(K43,1),"0,##") -> dcm_0,05_12,_24_0,6 | P43: passiver wdst
B44: 0.092 | C44: dcm | D44: =TEXT(ROUND(E44,3),"#,#")&"_"&TEXT(G44,"0") -> 12,_24 | E44: 12.0017 | F44: 0.1418 | G44: 24.03 | H44: 0.0595 | I44: =G44/E44 -> 2.0022164 | J44: =F44*E44 -> 1.7018411 | K44: =H44*G44 -> 1.429785 | L44: =J44-K44 -> 0.27205606 | M44: =K44/J44 -> 0.84014015 | N44: 400
B45: 0.1083 | C45: dcm | D45: =TEXT(ROUND(E45,3),"#,#")&"_"&TEXT(G45,"0") -> 12,_24 | E45: 12.0076 | F45: 0.23892 | G45: 24.016 | H45: 0.10025 | I45: =G45/E45 -> 2.0000666 | J45: =F45*E45 -> 2.8688558 | K45: =H45*G45 -> 2.407604 | L45: =J45-K45 -> 0.46125179 | M45: =K45/J45 -> 0.83922099 | N45: 240
B46: 0.162 | C46: dcm | D46: =TEXT(ROUND(E46,3),"#,#")&"_"&TEXT(G46,"0") -> 12,_24 | E46: 12.0076 | F46: 0.47781 | G46: 24.036 | H46: 0.20866 | I46: =G46/E46 -> 2.0017322 | J46: =F46*E46 -> 5.7373514 | K46: =H46*G46 -> 5.0153518 | L46: =J46-K46 -> 0.7219996 | M46: =K46/J46 -> 0.87415803 | N46: 115
B47: 0.208 | C47: dcm | D47: =TEXT(ROUND(E47,3),"#,#")&"_"&TEXT(G47,"0") -> 12,_24 | E47: 12.0096 | F47: 0.72157 | G47: 24.013 | H47: 0.31633 | I47: =G47/E47 -> 1.9994837 | J47: =F47*E47 -> 8.6657671 | K47: =H47*G47 -> 7.5960323 | L47: =J47-K47 -> 1.0697348 | M47: =K47/J47 -> 0.87655625 | N47: 76
...

Sheet Bildverzeichnis
A2: Oszi-Bild | B2: Thermo-Bild | C2: Ref [M_d_Vin_Vout_Pout] | D2: Ch1 | E2: CH2 | F2: CH3 | G2: CH4 | H2: comment
A3: tek00000 | B3: - | C3: =Wirkungsgradkurven!O15 -> dcm_0,273_3,3_24_1,2 | D3: SIG1 | E3: SIG2 | F3: IL11 | G3: IL21
A4: tek00001 | B4: - | C4: =Wirkungsgradkurven!O22 -> dcm_0,123_5,_12_0,5 | D4: SIG1 | E4: SIG2 | F4: IL11 | G4: IL21
A5: tek00002 | B5: - | C5: =Wirkungsgradkurven!O37 -> dcm_0,2303_5,_48_2,3 | D5: SIG1 | E5: SIG2 | F5: IL11 | G5: IL21
A6: tek00003 | B6: - | C6: =Wirkungsgradkurven!O43 -> dcm_0,05_12,_24_0,6 | D6: SIG1 | E6: SIG2 | F6: IL11 | G6: IL21
A7: tek00005 | B7: - | C7: =Wirkungsgradkurven!O53 -> ccm_0,27_12,_24_63,7 | D7: SIG1 | E7: SIG2 | F7: IL11 | G7: IL21 | H7: ccm, strombegrenzt durch Netzteil Ausgangsstrom
A8: tek00006 | B8: - | C8: =Wirkungsgradkurven!O55 -> dcm_0,1222_12,_48_2,3 | D8: SIG1 | E8: SIG2 | F8: IL11 | G8: IL21
A9: tek00004 | B9: - | C9: =Wirkungsgradkurven!O61 -> ccm_0,3787_12,_48_60,6 | D9: SIG1 | E9: SIG2 | F9: IL11 | G9: IL21 | H9: ccm, strombegrenzt durch Netzteil Ausgangsstrom
A10: tek00007 | B10: - | C10: =Wirkungsgradkurven!O63 -> dcm_0,0442_24,_48_2,3 | D10: SIG1 | E10: SIG2 | F10: IL11 | G10: IL21
A11: tek00008 | B11: - | C11: =Wirkungsgradkurven!O67 -> dcm_0,2093_24,_48_29,9 | D11: SIG1 | E11: SIG2 | F11: IL11 | G11: IL21
A12: tek00009 | B12: - | C12: =Wirkungsgradkurven!O68 -> ccm_0,2503_24,_48_50,1 | D12: SIG1 | E12: SIG2 | F12: IL11 | G12: IL21
A13: tek00010 | B13: - | C13: =Wirkungsgradkurven!O71 -> ccm_0,2532_24,_48_100,2 | D13: SIG1 | E13: SIG2 | F13: IL11 | G13: IL21
A14: tek00011 | B14: HM20260319174948 HM20260319175024 HM20260319175038 HM20260319175052 | C14: =Wirkungsgradkurven!O72 -> ccm_0,2548_24,_48_134,2 | D14: SIG1 | E14: SIG2 | F14: IL11 | G14: IL21 | H14: ccm, strombegrenzt durch Netzteil Ausgangsstrom
A15: - | B15: Ordner: | C15: =Wirkungsgradkurven!O50 -> ccm_0,263_12,_24_28,5 | D15: - | E15: - | F15: - | G15: - | H15: Ref Messung für Stationäre Messungen
A16: - | B16: Ordner: | C16: =Wirkungsgradkurven!O70 -> ccm_0,253_24,_48_92,9 | D16: - | E16: - | F16: - | G16: - | H16: Ref Messung für Stationäre Messungen

Sheet Messmittel
B2: Gerät | C2: Art | D2: Verwendung | E2: Anzahl
B3: Tektronix AFG3022B | C3: Funktionsgenerator | D3: Schalter-Ansteuersignal | E3: 1
B4: Tektronix MSO 3034 | C4: Digitales Oszilloskop | D4: Messsignale im Zeitbereich | E4: 1
B5: GWINSTEK SPD-3606 | C5: Labor Netzteil | D5: Versorgung DCDC, Treiber | E5: 1
B6: Tektronix DMM 4040 6-1/2 | C6: Digitales Multimeter | D6: Vout,Iout, Vin, Iin RMS Messung | E6: 4
B7: GOSSEN METRAWATT 32EL300R30 | C7: Elektronische Last | D7: Stellbare Ohm'sche Last | E7: 1
B8: HIKMICRO HM-TP42-3AQF/W-Pocket2 | C8: Thermo Kamera | D8: Halbleiter Temperaturüberwachung | E8: 1
B9: Passiver Leistungswiderstand mit Kühlkörper | C9: 1k Ohm Leistungswiderstand | D9: Ohmsche Last | E9: 1
B10: TCP202 AC/DC Current Probe | C10: Strommesszange | D10: Isolierte Strommessung im Zeitbereich | E10: 2
